Workbook

Sheet Inputs
A1: Variable | B1: Description | C1: Units | D1: Value | E1: Experimental Value | F1: Value Used
A2: PLANT
A3: otp | B3: Operating Time | C3: hr/yr | D3: 8000 | F3: =IF(ISBLANK(E3),D3,E3) -> 8000
A4: qcow | B4: manure produced by cows on average | C4: kg/d-cow | D4: 53.8 | F4: =IF(ISBLANK(E4),D4,E4) -> 53.8
A5: dcow | B5: distance to travel for manure collection | C5: mi | D5: 60 | F5: =IF(ISBLANK(E5),D5,E5) -> 60
A6: dfw | B6: distance to travel for food waste collection | C6: mi | D6: 60 | F6: =IF(ISBLANK(E6),D6,E6) -> 60
A7: tmpg | B7: transportation fuel consumption | C7: mi/gal | D7: 0.45 | F7: =IF(ISBLANK(E7),D7,E7) -> 0.45
A8: tspd | B8: speed of transportation vehicle | C8: mi/hr | D8: 60 | F8: =IF(ISBLANK(E8),D8,E8) -> 60
A9: pump_efficiency | B9: effeciency of the pumps | C9: %/100 | D9: 0.7 | F9: =IF(ISBLANK(E9),D9,E9) -> 0.7
F10: =IF(ISBLANK(E10),D10,E10) -> 0
F11: =IF(ISBLANK(E11),D11,E11) -> 0
A12: Feedstock Characteristics | F12: =IF(ISBLANK(E12),D12,E12) -> 0 | H12: Total Plant Flow Rates
A13: qow | B13: organic waste feedstock flow rate | C13: kg/hr | D13: 150000 | E13: 25000 | F13: =IF(ISBLANK(E13),D13,E13) -> 25000 | H13: m3/hr | J13: ton/hr | L13: ton/yr | N13: ton/d
A14: pfw | B14: percentage of food waste in feedstock | C14: %/100 | D14: 0.1 | F14: =IF(ISBLANK(E14),D14,E14) -> 0.1 | H14: Path A | I14: Path AB | J14: Path A | K14: Path AB | L14: Path A | M14: Path AB | N14: Path A | O14: Path AB
A15: ppoo | B15: percentage of manure in feedstock | C15: %/100 | D15: 0.9 | F15: =IF(ISBLANK(E15),D15,E15) -> 0.9 | H15: =F13/1050 -> 23.809524 | I15: =F13/(1050)*2 -> 47.619048 | J15: =Inputs!F13/Units!C45 -> 27.557775 | K15: =Inputs!F13/(Units!C45)*2 -> 55.11555 | L15: =J15*Units!C55*Units!C52 -> 241406.11 | M15: =K15*Units!C55*Units!C52 -> 482812.22 | N15: =J15*Units!C55 -> 661.3866 | O15: =N15*2 -> 1322.7732
A16: pcow | B16: percentage of manure from cattle in feedstock | C16: %/100 | D16: 0.6 | F16: =IF(ISBLANK(E16),D16,E16) -> 0.6
A17: ppig | B17: percentage of manure from pigs in feedstock | C17: %/100 | D17: 0.4 | F17: =IF(ISBLANK(E17),D17,E17) -> 0.4
F18: =IF(ISBLANK(E18),D18,E18) -> 0
F19: =IF(ISBLANK(E19),D19,E19) -> 0
F20: =IF(ISBLANK(E20),D20,E20) -> 0
A21: Raw Food Waste Characteristics | F21: =IF(ISBLANK(E21),D21,E21) -> 0
A22: fw_tss | B22: total suspended solids in mixed food waste | C22: g TS / g FW | D22: 0.4052 | F22: =IF(ISBLANK(E22),D22,E22) -> 0.4052
A23: fw_vss | B23: total volatile suspended solids in mixed food waste | C23: g VS / g FW | D23: 0.3996 | F23: =IF(ISBLANK(E23),D23,E23) -> 0.3996
A24: fw_tcod | B24: total chemical oxygen demand in mixed food waste | C24: mg/L | D24: 1500 | F24: =IF(ISBLANK(E24),D24,E24) -> 1500
A25: fw_scod | B25: soluble chemical oxygen demand in mixed food waste | C25: mg/L | D25: 670 | F25: =IF(ISBLANK(E25),D25,E25) -> 670
A26: fw_pcod | B26: particulate chemical oxygen demand in mixed food waste | C26: mg/L | D26: 870 | F26: =IF(ISBLANK(E26),D26,E26) -> 870
A27: fw_tbod | B27: total biological oxygen demand in mixed food waste | C27: mg/L | D27: 580 | F27: =IF(ISBLANK(E27),D27,E27) -> 580
A28: fw_sbod | B28: soluble biological oxygen demand in mixed food waste | C28: mg/L | D28: 190 | F28: =IF(ISBLANK(E28),D28,E28) -> 190
A29: fw_pbod | B29: particulate biological oxygen demand in mixed food waste | C29: mg/L | D29: 380 | F29: =IF(ISBLANK(E29),D29,E29) -> 380
A30: fw_tn | B30: total nitrogen in mixed food waste | C30: g/g DM | D30: 0.025 | F30: =IF(ISBLANK(E30),D30,E30) -> 0.025
A31: fw_son | B31: soluble organic nitrogen in mixed food waste | C31: g/g TN | D31: 0.29 | F31: =IF(ISBLANK(E31),D31,E31) -> 0.29
A32: fw_pn | B32: particulate nitrogen in mixed food waste | C32: g/g TN | D32: 0.69 | F32: =IF(ISBLANK(E32),D32,E32) -> 0.69
A33: fw_nh3_n | B33: amount of nitrogen present as ammonia in mixed food waste | C33: g/g TN | D33: 0.02 | F33: =IF(ISBLANK(E33),D33,E33) -> 0.02
... A39: fw_C | B39: the percentage of carbon in food waste (m:m) | C39: %/100 | D39: 0.5 | F39: =IF(ISBLANK(E39),D39,E39) -> 0.5
F40: =IF(ISBLANK(E40),D40,E40) -> 0
F41: =IF(ISBLANK(E41),D41,E41) -> 0
A42: Digested Cattle Manure Characteristics | F42: =IF(ISBLANK(E42),D42,E42) -> 0
A43: cow_tss | B43: total suspended solids in manure | C43: g TS / g M | D43: 0.229 | F43: =IF(ISBLANK(E43),D43,E43) -> 0.229
A44: cow_vss | B44: volatile suspended solids in manure | C44: g VS / g M | D44: 0.1793 | F44: =IF(ISBLANK(E44),D44,E44) -> 0.1793
A45: cow_pH | B45: aqueous pH of cattle manure | D45: 7.4 | F45: =IF(ISBLANK(E45),D45,E45) -> 7.4
...

Sheet Units
A1: Unit Conversions
A2: Volume | G2: kg COD/m3 sludge to g/L liquid digestate
A3: 1 | B3: gal | C3: 3.785 | D3: L | G3: kg COD | H3: 1000 g | I3: mol | J3: g | K3: m3 | L3: L sludge
A4: 1 | B4: gal | C4: 3.9 | D4: kg - sludge | G4: m3 | H4: 1kg | I4: g COD | J4: mol | K4: 1050 L sludge | L4: L digestate
A5: 1 | B5: gal | C5: 3.785 | D5: kg - water
A6: 1 | B6: yd3 | C6: 0.76455 | D6: m3 | G6: mol/L to kg/m3
A7: 1 | B7: ft3 | C7: 0.028168 | D7: m3 | G7: mol | H7: g | I7: 1000 L | J7: kg
A8: 1 | B8: oz | C8: 0.0295735 | D8: L | G8: L | H8: mol | I8: m3 | J8: 1000 g
A9: 1 | B9: m3 | C9: 6.29 | D9: barrels
A10: 1 | B10: gal | C10: 3.03 | D10: kg - jet fuel | G10: sludge to ld
G11: g | H11: L sludge | I11: hr
A12: Density at STP | G12: L sludge | H12: hr | I12: L digest
A13: 1 | B13: L water | C13: 1 | D13: kg
A14: 1 | B14: m3 water | C14: 1000 | D14: L
A15: 1 | B15: m3 water | C15: 1000 | D15: kg
A16: 1 | B16: L sludge | C16: 1.5 | D16: kg
A17: 1 | B17: m3 sludge | C17: 1050 | D17: L
A18: 1 | B18: m3 sludge | C18: 1050 | D18: kg
A19: 1 | B19: L acetone | C19: 749.4 | D19: g
A20: 1 | B20: L butanol | C20: 810 | D20: g
A21: 1 | B21: L ethanol | C21: 0.789 | D21: kg
A22: 1 | B22: m3 ethanol | C22: 789 | D22: kg
A23: 1 | B23: L acetic acid | C23: 1049 | D23: g
A24: 1 | B24: L butyric acid | C24: 964 | D24: g
A25: 1 | B25: mL Amb-37 | C25: 1.2 | D25: g
A26: =A25/(C81*C14) -> 1 | B26: m3 Amb-37 | C26: =C25*C84 -> 1200 | D26: kg
A27: 1 | B27: cm3 Pd/C | C27: 3.71 | D27: g
A28: =A27/C82 -> 100 | B28: m3 Pd/C | C28: =C27*C84 -> 3710 | D28: kg
A29: 1 | B29: m3 CH4 gas | C29: 0.657 | D29: kg
A30: 1 | B30: m3 CO2 | C30: 1.98 | D30: kg
A31: 1 | B31: m3 H2 | C31: 0.09 | D31: kg
A32: 1 | B32: m3 N2 gas | C32: 1.25 | D32: kg
A33: 1 | B33: m3 H2S | C33: 1.36 | D33: kg
A34: 1 | B34: m3 Biosolids | C34: =1.78*(C85/C84) -> 1780 | D34: kg
A35: 1 | B35: m3 Glucose | C35: 1560 | D35: kg
A36: Cheese Whey | B36: 1 m3 | C36: 400 | D36: kg
A37: 1 | B37: L Ideal Gas STP | C37: =1/22.414 -> 0.044614973 | D37: mol
A39: Length
A40: 1 | B40: acre | C40: 4047 | D40: m2
A41: 1 | B41: ft | C41: 12 | D41: in
...

Sheet ExpBase
A1: SEA WATER BIPOLAR MEMBRANE ELECTRODIALYSIS
A2: Operating Conditions
A3: Parameter | B3: Unit | C3: Value
A4: electrodialysis operating time | B4: hr | C4: 6
A5: electrodialysis operating temperature | B5: K | C5: 298.15
A6: electrodialysis flow rate within the compartments | B6: L/hr | C6: 18
A7: constant applied current per membrane pair | B7: A/mp | C7: 0.3
A8: maximum applied voltage per membrane pair | B8: V/mp | C8: 2
A9: minimum applied volate per membrane pair | B9: V/mp | C9: 1
A10: electrolyte concentration | B10: g/L | C10: 10
A11: diluate to concentrate volume ratio | B11: L/L | C11: 5
A12: dilute to electrolyte volume ratio | B12: L/L | C12: 5
A13: membrane surface area | B13: m2 | C13: 1
A14: membrane thickness | B14: m | C14: 0.01
A15: distance between electrodes | B15: m | C15: 4.5
... A27: ratio of tank height to diameter | B27: m:m | C27: 1.2
A30: Species by Compartment
A31: Parameter | B31: Unit | C31: Value
A32: LD_sodium | B32: %/100 | C32: 0.12
A33: LD_chlorine | B33: %/100 | C33: 0.08
A34: LD_sulfur | B34: %/100 | C34: 0.11
A35: LD_magnesium | B35: %/100 | C35: 0.06
A36: LD_calcium | B36: %/100 | C36: 0.04
A37: LD_potassium | B37: %/100 | C37: 0.02
A38: LD_pH | C38: =C4 -> 6
A39: A1_sodium | B39: %/100 | C39: 0.08
A40: A1_chlorine | B40: %/100 | C40: 0.85
A41: A1_sulfur | B41: %/100 | C41: =0.70005+0.2 -> 0.90005
A42: A1_magnesium | B42: %/100 | C42: 0.05
A43: A1_calcium | B43: %/100 | C43: 0.02
A44: A1_potassium | B44: %/100 | C44: 0.01
A45: A1_pH | C45: 1
A46: B1_sodium | B46: %/100 | C46: 0.76
A47: B1_chlorine | B47: %/100 | C47: 0.08
A48: B1_sulfur | B48: %/100 | C48: 0.03
A49: B1_magnesium | B49: %/100 | C49: 0.87
A50: B1_calcium | B50: %/100 | C50: 0.93
A51: B1_potassium | B51: %/100 | C51: 0.95
A52: B1_pH | C52: 13
A53: EL_sodium | B53: %/100 | C53: =1-SUM(C32,C39,C46) -> 0.04
...

Sheet Carbon
A1: CARBON FLOW RATES
A3: Chesse Whey Fermentation
A4: Parameter | B4: Unit | C4: Value | D4: Unit | E4: Carbon | F4: Unit | G4: Carbon Flow Rate | H4: Unit | I4: Total Carbon Flow | J4: TYPE
A5: Fermentation
A6: IN
A7: Lactose in Substrate | B7: g/hr | C7: =ExpBase!E125*ExpBase!C143 -> 2112492.3 | D7: g/hr | E7: =C7*Units!D493 -> 889505.54 | F7: MT/hr | G7: =E7/(Units!C$85) -> 0.88950554 | H7: =F7 -> MT/hr | I7: =G7 -> 0.88950554 | J7: CHEESE WHEY
A8: OUT
A9: Glucose Flow Rate | B9: g/hr | C9: =ExpBase!C139*ExpBase!C143 -> 89358.426 | D9: g/hr | E9: =C9*Units!D491 -> 35745.156 | F9: MT/hr | G9: =E9/(Units!C$85) -> 0.035745156
A10: Galactose Flow Rate | B10: g/hr | C10: =ExpBase!C140*ExpBase!C143 -> 204066.76 | D10: g/hr | E10: =C10*Units!D492 -> 81630.782 | F10: MT/hr | G10: =E10/(Units!C$85) -> 0.081630782
A11: Lactose Flow Rate | B11: g/hr | C11: =ExpBase!C141*ExpBase!C143 -> 147874.46 | D11: g/hr | E11: =C11*Units!D493 -> 62265.388 | F11: MT/hr | G11: =E11/(Units!C$85) -> 0.062265388
A12: Lactic Acid Flow Rate | B12: g/hr | C12: =ExpBase!C138*ExpBase!C143 -> 1671192.7 | D12: g/hr | E12: =C12*Units!D494 -> 668495.63 | F12: MT/hr | G12: =E12/(Units!C$85) -> 0.66849563 | H12: =F12 -> MT/hr | I12: =SUM(G9:G12) -> 0.84813696 | J12: FERMENTATION BROTH
A13: WASTE | H13: MT/hr | I13: =I7-I12 -> 0.041368585 | J13: WASTE WHEY
A14: Separation
A15: IN | H15: =H12 -> MT/hr | I15: =I12 -> 0.84813696 | J15: FERMENTATION BROTH
A16: OUT
A17: Lactic Acid Flow Rate | B17: g/hr | C17: =C12*ExpBase!C174 -> 1654480.8 | D17: g/hr | E17: =C17*Units!D494 -> 661810.67 | F17: MT/hr | G17: =E17/Units!C$85 -> 0.66181067
A18: Glucose Flow Rate | B18: g/hr | C18: =C9*ExpBase!C174 -> 88464.842 | D18: g/hr | E18: =C18*Units!D491 -> 35387.705 | F18: MT/hr | G18: =E18/Units!C$85 -> 0.035387705
A19: Galactose Flow Rate | B19: g/hr | C19: =C10*ExpBase!C174 -> 202026.09 | D19: g/hr | E19: =C19*Units!D492 -> 80814.474 | F19: MT/hr | G19: =E19/Units!C$85 -> 0.080814474
A20: Lactose Flow Rate | B20: g/hr | C20: =C11*ExpBase!C174 -> 146395.72 | D20: g/hr | E20: =C20*Units!D493 -> 61642.734 | F20: MT/hr | G20: =E20/Units!C$85 -> 0.061642734 | H20: MT/hr | I20: =SUM(G17:G20) -> 0.83965559 | J20: CONCENTRATED LACTATE
A21: WASTE | H21: MT/hr | I21: =I15-I20 -> 0.0084813696 | J21: WASTE WATER
A24: Anaerobic Digestion
A25: Parameter | B25: Unit | C25: Value | D25: Unit | E25: Carbon | F25: Unit | G25: Carbon Flow Rate | H25: Unit | I25: Total Carbon Flow | J25: TYPE
A26: Manure Digestion
A27: IN
A28: Manure | B28: kg/hr | C28: =Inputs!F13*Inputs!F15 -> 22500 | D28: mg/hr | E28: =C28*ExpBase!C310*Inputs!D47 -> 1.476673e+09 | F28: MT/hr | G28: =E28/Units!C$86 -> 1.476673 | H28: MT/hr | I28: =SUM(G28) -> 1.476673 | J28: FEED
A29: Biosolid Recycle | D29: mg/hr | E29: =E28*0.2 -> 2.9533459e+08 | F29: MT/hr | G29: =E29/Units!C$86 -> 0.29533459 | H29: MT/hr | I29: =G29 -> 0.29533459 | J29: BIOSOLID RECYCLE
A30: BIOGAS
A31: Methane | B31: L/hr | C31: =ExpBase!G363 -> 11697.475 | D31: g/hr | E31: =C31*Units!D495*0.72 -> 6306.66 | F31: MT/hr | G31: =E31/Units!C85 -> 0.00630666 | H31: MT/hr | I31: =SUM(G31:G32) -> 0.10433521 | J31: BIOGAS
A32: Carbon Dioxide | B32: L/hr | C32: =ExpBase!G364 -> 183260.44 | D32: g/hr | E32: =C32*Units!D496*1.96 -> 98028.553 | F32: MT/hr | G32: =E32/Units!C85 -> 0.098028553 | N32: =I28+I46 -> 2.726673
A33: ACIDS | K33: =I34/SUM(I28:I29) -> 0.052366783 | N33: =0.8783/N32 -> 0.32211417
A34: Lactate Produced | B34: kg/hr | C34: =ExpBase!G251 -> 0.99389647 | D34: kg/hr | E34: =C34*Units!D494 -> 0.39756962 | F34: MT/hr | G34: =E34/1000 -> 0.00039756962 | H34: MT/hr | I34: =SUM(G34:G42) -> 0.092794335 | J34: VFAS | N34: =0.27/N32 -> 0.099021776
A35: Acetate Produced | B35: kg/hr | C35: =ExpBase!G252 -> 61.817073 | D35: kg/hr | E35: =C35*Units!D498 -> 25.151926 | F35: MT/hr | G35: =E35/1000 -> 0.025151926
A36: Propionic Production | B36: kg/hr | C36: =ExpBase!G253 -> 0 | D36: kg/hr | E36: =C36*Units!D499 -> 0 | F36: MT/hr | G36: =E36/1000 -> 0 | K36: 0.05093481
A37: Butyric Production | B37: kg/hr | C37: =ExpBase!G254 -> 63.607112 | D37: kg/hr | E37: =C37*Units!D500 -> 35.08542 | F37: MT/hr | G37: =E37/1000 -> 0.03508542 | K37: 0.058879666
A38: Isobutyric Production | B38: kg/hr | C38: =ExpBase!G255 -> 2.9168895 | D38: kg/hr | E38: =C38*Units!D501 -> 1.6089442 | F38: MT/hr | G38: =E38/1000 -> 0.0016089442
A39: Valerate Production | B39: kg/hr | C39: =ExpBase!G256 -> 37.531416 | D39: kg/hr | E39: =C39*Units!D502 -> 22.289846 | F39: MT/hr | G39: =E39/1000 -> 0.022289846
A40: Isovaleric Production | B40: kg/hr | C40: =ExpBase!G257 -> 0 | D40: kg/hr | E40: =C40*Units!D503 -> 0 | F40: MT/hr | G40: =E40/1000 -> 0
A41: Caproic Production | B41: kg/hr | C41: =ExpBase!G258 -> 13.19917 | D41: kg/hr | E41: =C41*Units!D504 -> 8.2606287 | F41: MT/hr | G41: =E41/1000 -> 0.0082606287
A42: Heptanoate Production | B42: kg/hr | C42: =ExpBase!G259 -> 0 | D42: kg/hr | E42: =C42*Units!D505 -> 0 | F42: MT/hr | G42: =E42/1000 -> 0
A44: Food Waste Digestion
...

Sheet CostCalc
A1: CALCULATIONS - CAPEX
A6: Transportation
A7: Parameter | B7: Size Required
B8: Size | C8: Unit | D8: Cost | E8: Unit
A10: Manure | B10: =Inputs!F13*(Inputs!F15)/Units!C15 -> 22.5 | C10: m3/hr
B11: =B10*Units!C5 -> 85.1625 | C11: yd3/hr
A12: Food Waste | B12: =Inputs!F13*(Inputs!F14)/Units!C15 -> 2.5 | C12: m3/hr
B13: =B12*Units!C5 -> 9.4625 | C13: yd3/hr
A14: Total | B14: =SUM(B10,B12) -> 25 | C14: m3/hr
B15: =B14*Units!C$5 -> 94.625 | C15: yd3/hr
B16: =B15*Units!C$55 -> 2271 | C16: yd3/day
A17: Distance | B17: 242 | C17: mi/round trip
A18: Truck Speed | B18: =Inputs!F8 -> 60 | C18: mi/hr
A19: Time | B19: =B17/B18 -> 4.0333333 | C19: hr/trip
A20: Trips | B20: =8/B19 -> 1.9834711 | C20: trip/day
A21: Truck Size | B21: 40 | C21: yd3/trip
B22: =B21*B20 -> 79.338843 | C22: yd3/day
A23: Number of Trucks | B23: =ROUNDUP((B16/B22)*1.5,0) -> 43 | C23: truck
A26: Cheese Whey | B26: 25.78 | C26: m3/hr
A27: Total | B27: =B26 -> 25.78 | C27: m3/hr
B28: =B27*Units!C$5 -> 97.5773 | C28: yd3/hr
B29: =B28*Units!C$55 -> 2341.8552 | C29: yd3/day
A30: Distance | B30: 190 | C30: mi/round trip
A31: Truck Speed | B31: 60 | C31: mi/hr
A32: Time | B32: =B30/B31 -> 3.1666667 | C32: hr/trip
A33: Trips | B33: =8/B32 -> 2.5263158 | C33: trip/day
A34: Truck Size | B34: 40 | C34: yd3/trip
B35: =B34*B33 -> 101.05263 | C35: yd3/day
A36: Number of Trucks | B36: =ROUNDUP((B29/B35)*1.5,0) -> 35 | C36: truck
A38: Ocean Water | B38: =ExpBase!Q102 -> 33.955948 | C38: m3/hr
A39: Total | B39: =B38 -> 33.955948 | C39: m3/hr
B40: =B39*Units!C$5 -> 128.52326 | C40: yd3/hr
B41: =B40*Units!C$55 -> 3084.5584 | C41: yd3/day
A42: Distance | B42: 170 | C42: mi/round trip
A43: Truck Speed | B43: 60 | C43: mi/hr
A44: Time | B44: =B42/B43 -> 2.8333333 | C44: hr/trip
A45: Trips | B45: =8/B44 -> 2.8235294 | C45: trip/day
A46: Truck Size | B46: 40 | C46: yd3/trip
B47: =B46*B45 -> 112.94118 | C47: yd3/day
A48: Number of Trucks | B48: =ROUNDUP((B41/B47)*1.5,0) -> 41 | C48: truck
...

Sheet Locate
A1: LOCATION ANALYSIS
A4: Parameter | B4: Description | C4: Unit | D4: Value
A5: San Francisco, CA
A6: Food Waste | B6: compost collected | C6: ton/day | D6: 500
C7: kg/d | D7: =D6*Units!C45 -> 453592.5
C8: kg/hr | D8: =D7/Units!C55 -> 18899.688
C9: m3/hr | D9: =D8/Units!C18 -> 17.999702
A10: capita | B10: population of san francisco | C10: # | D10: 808437
A11: fw_cap | B11: food waste per person | C11: m3/hr-cap | D11: =D9/D10 -> 2.2264818e-05
A12: Harris Ranch | B12: 29475 Fresno Coalinga Road, Coalinga CA
A13: Manure | B13: number of cows | C13: # | D13: 250000
B14: Coalinga, CA 93210 | C14: kg/d | D14: =D13*Inputs!F4 -> 13450000
C15: kg/hr | D15: =D14/Units!C55 -> 560416.67
C16: m3/hr | D16: =D15/Units!C18 -> 533.73016
B17: TOTAL | C17: m3/hr | D17: =D9+D16 -> 551.72986
B18: Distance Between FW and Manure | C18: mi | D18: 182
A19: FW/M | B19: Ratio food waste to manure | D19: =D8/D15 -> 0.033724349
A21: Austin, TX
A22: Food Waste | B22: compost collected | C22: ton/yr | D22: 138955
C23: kg/yr | D23: =D22*Units!C45 -> 1.2605789e+08
C24: kg/hr | D24: =D23/(Units!C52*Units!C55) -> 14390.17
C25: m3/hr | D25: =D24/Units!C18 -> 13.704924
A26: capita | B26: population of austin | C26: # | D26: 974447
A27: fw_capita | B27: food waste per person | C27: m3/hr-cap | D27: =D25/D26 -> 1.4064309e-05
A30: Berkeley, CA
A31: Food Waste | B31: compost collected | C31: ton/mon | D31: 1800
C32: kg/mon | D32: =D31*Units!C45 -> 1632933
C33: kg/hr | D33: =D32/(Units!C54*Units!C55) -> 2267.9625
C34: m3/hr | D34: =D33/Units!C18 -> 2.1599643
A35: capita | B35: population of berkeley | C35: # | D35: 118950
A36: fw_cap | B36: food waste per person | C36: m3/hr-cap | D36: =D34/D35 -> 1.815859e-05
A38: Fort Collins, CO
A39: Food Waste | B39: theoretical compost collected | C39: kg/hr | D39: =Inputs!D13*Inputs!D14 -> 15000
C40: m3/hr | D40: =D39/Units!C18 -> 14.285714
A41: capita | B41: population of fort collins area | C41: # | D41: 359000
A42: fw_capita | B42: food waste per person | C42: m3/hr-cap | D42: =D40/D41 -> 3.9793076e-05
A44: AVERAGE
A45: avg_fwc | B45: average food waste production per capita | C45: m3/hr-cap | D45: =AVERAGE(D11,D27,D36,D42) -> 2.3570198e-05
A46: sd_fwc | B46: standard deviation of fw production per cap | C46: m3/hr-cap | D46: =_xlfn.STDEV.P(D11,D27,D36,D42) -> 9.8047591e-06
A47: US_pop | B47: population of the US | C47: cap | D47: =333300000 -> 333300000
...

Sheet CAPEX
A1: CAPITAL EXPENSE
M3: April 2026 PPI | N3: 402.486
A5: Transportation
A7: Total Capital Investment
A8: Mechanical Equipment List | F8: Researched Values | K8: Scaled Installed in Current Year Factors | O8: Total Cost
A9: Equipment Name | B9: Size | C9: Unit | D9: Number Required | E9: Material | F9: Cost | G9: Size | H9: Unit | I9: Year | J9: Source | K9: Scaling Exponent | L9: Installation Factor | M9: Size Ratio | N9: PPI
N10: 2024
A11: Boats - Ocean Water | B11: 1 | C11: boat | D11: 2 | E11: Oceanographic Research Vessel, 100 ft | F11: 20000000 | G11: 1 | H11: boat | I11: 2024 | K11: 1 | L11: 1 | M11: =B11/G11 -> 1 | N11: =N$3/N$3 -> 1 | O11: =D11*N11*F11*L11*M11^(K11) -> 40000000
A12: Diesel Trucks - Ocean Water | B12: 40 | C12: yd3 | D12: =CostCalc!B48 -> 41 | E12: Peterbilt Front Loader | F12: =Inputs!F$844*G12 -> 355000 | G12: 40 | H12: yd3 | I12: 2024 | K12: 1 | L12: 1 | M12: =B12/G12 -> 1 | N12: =N$3/N$3 -> 1 | O12: =D12*N12*F12*L12*M12^(K12) -> 14555000
A13: Diesel Trucks - Cheese Whey | B13: 40 | C13: yd3 | D13: =CostCalc!B36 -> 35 | E13: Peterbilt Front Loader | F13: =Inputs!F$844*G13 -> 355000 | G13: 40 | H13: yd3 | I13: 2024 | K13: 1 | L13: 1 | M13: =B13/G13 -> 1 | N13: =N$3/N$3 -> 1 | O13: =D13*N13*F13*L13*M13^(K13) -> 12425000
A14: Diesel Trucks - Organic Waste | B14: =CostCalc!B21 -> 40 | C14: yd3 | D14: =CostCalc!B23 -> 43 | E14: Peterbilt Front Loader | F14: =Inputs!F$844*G14 -> 355000 | G14: 40 | H14: yd3 | I14: 2024 | K14: 1 | L14: 1 | M14: =B14/G14 -> 1 | N14: =N$3/N$3 -> 1 | O14: =D14*N14*F14*L14*M14^(K14) -> 15265000
A15: Hydraulic Truck Dump with Scale | B15: =CostCalc!B51 -> 37301.593 | C15: lb/hr | D15: 2 | F15: 80000 | G15: 367.437 | H15: lb/hr | I15: 1998 | K15: 0.6 | L15: 2.47 | M15: =B15/G15 -> 101.51834 | N15: =N$3/142.2 -> 2.8304219 | O15: =D15*N15*F15*L15*M15^(K15) -> 17889360
A17: Total: | O17: =SUM(O11:O15) -> 1.0013436e+08
A20: Inoculum Development
A22: Total Capital Investment
A23: Mechanical Equipment List | F23: Researched Values | K23: Scaled Installed in Current Year Factors | O23: Total Cost
A24: Equipment Name | B24: Size | C24: Unit | D24: Number Required | E24: Material | F24: Cost | G24: Size | H24: Unit | I24: Year | J24: Source | K24: Scaling Exponent | L24: Installation Factor | M24: Size Ratio | N24: PPI
N25: 2024
A26: Feed Pump - Caprociproducens | C26: kg/hr | E26: 316 Stainless Steel | F26: 11358 | G26: 43149 | H26: kg/hr | I26: 2018 | K26: 0.8 | L26: 2.3 | M26: =B26/G26 -> 0 | N26: =N$3/329.7 -> 1.2207643
A27: Tank Wall - Caprociproducens | C27: m3 | D27: =CostCalc!D$289 -> 4 | E27: Concrete | F27: =Inputs!F$847 -> 188.34 | G27: 0.76 | H27: m3 | I27: 2022 | J27: 2 | K27: 0.7 | L27: 2.6 | M27: =B27/G27 -> 0 | N27: =N$3/432.15 -> 0.93135717
A28: Insulation - Caprociproducens | C28: m2 | D28: =D$179 -> 2 | E28: Unfaced Fiberglass | F28: =Inputs!F$848 -> 8.35 | G28: 0.09 | H28: m2 | I28: 2022 | J28: 3 | K28: 1 | L28: 2.6 | M28: =B28/G28 -> 0 | N28: =N$3/432.15 -> 0.93135717
A29: Gas Cover - Caprociproducens | C29: m3 | D29: 2 | E29: Double Membrane Polyvinylidene Fluoride 1.5 mm, Pressure and Volume Sensor | F29: =Inputs!F$850*CostCalc!G$300 -> 32000.06 | G29: 1000 | H29: m3 | I29: 2023 | K29: 1 | L29: 2.6 | M29: =B29/G29 -> 0 | N29: =N$3/421.24 -> 0.95547906
A30: Agitator - Caprociproducens | C30: hp | D30: =D$180 -> 2 | E30: Stainless Steel, Fixed Propeller, 3 Impellers, 2 Blades, Motor, Gear drive | F30: =Inputs!F$849*G30 -> 600 | G30: 1 | H30: hp | I30: 1998 | J30: 4 | K30: 0.5 | L30: 1.5 | M30: =B30/G30 -> 0 | N30: =N$3/142.2 -> 2.8304219
A31: Feed Pump - Lignocellulose | C31: kg/hr | E31: 316 Stainless Steel | F31: 11358 | G31: 43149 | H31: kg/hr | I31: 2018 | K31: 0.8 | L31: 2.3 | M31: =B31/G31 -> 0 | N31: =N$3/329.7 -> 1.2207643
A32: Tank Wall - Lignocellulose | C32: m3 | D32: =CostCalc!D$289 -> 4 | E32: Concrete | F32: =Inputs!F$847 -> 188.34 | G32: 0.76 | H32: m3 | I32: 2022 | J32: 2 | K32: 0.7 | L32: 2.6 | M32: =B32/G32 -> 0 | N32: =N$3/432.15 -> 0.93135717
A33: Insulation - Lignocellulose | C33: m2 | D33: =D$179 -> 2 | E33: Unfaced Fiberglass | F33: =Inputs!F$848 -> 8.35 | G33: 0.09 | H33: m2 | I33: 2022 | J33: 3 | K33: 1 | L33: 2.6 | M33: =B33/G33 -> 0 | N33: =N$3/432.15 -> 0.93135717
A34: Gas Cover - Lignocellulose | C34: m3 | D34: 2 | E34: Double Membrane Polyvinylidene Fluoride 1.5 mm, Pressure and Volume Sensor | F34: =Inputs!F$850*CostCalc!G$300 -> 32000.06 | G34: 1000 | H34: m3 | I34: 2023 | K34: 1 | L34: 2.6 | M34: =B34/G34 -> 0 | N34: =N$3/421.24 -> 0.95547906
A35: Agitator - Lignocellulose | C35: hp | D35: =D$180 -> 2 | E35: Stainless Steel, Fixed Propeller, 3 Impellers, 2 Blades, Motor, Gear drive | F35: =Inputs!F$849*G35 -> 600 | G35: 1 | H35: hp | I35: 1998 | J35: 4 | K35: 0.5 | L35: 1.5 | M35: =B35/G35 -> 0 | N35: =N$3/142.2 -> 2.8304219
A36: Feed Pump - Cl. Klu | C36: kg/hr | E36: 316 Stainless Steel | F36: 11358 | G36: 43149 | H36: kg/hr | I36: 2018 | K36: 0.8 | L36: 2.3 | M36: =B36/G36 -> 0 | N36: =N$3/329.7 -> 1.2207643
A37: Tank Wall - Cl. Klu | C37: m3 | D37: =CostCalc!D$289 -> 4 | E37: Concrete | F37: =Inputs!F$847 -> 188.34 | G37: 0.76 | H37: m3 | I37: 2022 | J37: 2 | K37: 0.7 | L37: 2.6 | M37: =B37/G37 -> 0 | N37: =N$3/432.15 -> 0.93135717
A38: Insulation - Cl. Klu | C38: m2 | D38: =D$179 -> 2 | E38: Unfaced Fiberglass | F38: =Inputs!F$848 -> 8.35 | G38: 0.09 | H38: m2 | I38: 2022 | J38: 3 | K38: 1 | L38: 2.6 | M38: =B38/G38 -> 0 | N38: =N$3/432.15 -> 0.93135717
A39: Gas Cover - Cl. Klu | C39: m3 | D39: 2 | E39: Double Membrane Polyvinylidene Fluoride 1.5 mm, Pressure and Volume Sensor | F39: =Inputs!F$850*CostCalc!G$300 -> 32000.06 | G39: 1000 | H39: m3 | I39: 2023 | K39: 1 | L39: 2.6 | M39: =B39/G39 -> 0 | N39: =N$3/421.24 -> 0.95547906
A40: Agitator - Cl. Klu | C40: hp | D40: =D$180 -> 2 | E40: Stainless Steel, Fixed Propeller, 3 Impellers, 2 Blades, Motor, Gear drive | F40: =Inputs!F$849*G40 -> 600 | G40: 1 | H40: hp | I40: 1998 | J40: 4 | K40: 0.5 | L40: 1.5 | M40: =B40/G40 -> 0 | N40: =N$3/142.2 -> 2.8304219
A41: Feed Pump - Cl. Lj | C41: kg/hr | E41: 316 Stainless Steel | F41: 11358 | G41: 43149 | H41: kg/hr | I41: 2018 | K41: 0.8 | L41: 2.3 | M41: =B41/G41 -> 0 | N41: =N$3/329.7 -> 1.2207643
A42: Tank Wall - Cl. Lj | C42: m3 | D42: =CostCalc!D$289 -> 4 | E42: Concrete | F42: =Inputs!F$847 -> 188.34 | G42: 0.76 | H42: m3 | I42: 2022 | J42: 2 | K42: 0.7 | L42: 2.6 | M42: =B42/G42 -> 0 | N42: =N$3/432.15 -> 0.93135717
A43: Insulation - Cl. Lj | C43: m2 | D43: =D$179 -> 2 | E43: Unfaced Fiberglass | F43: =Inputs!F$848 -> 8.35 | G43: 0.09 | H43: m2 | I43: 2022 | J43: 3 | K43: 1 | L43: 2.6 | M43: =B43/G43 -> 0 | N43: =N$3/432.15 -> 0.93135717
A44: Gas Cover - Cl. Lj | C44: m3 | D44: 2 | E44: Double Membrane Polyvinylidene Fluoride 1.5 mm, Pressure and Volume Sensor | F44: =Inputs!F$850*CostCalc!G$300 -> 32000.06 | G44: 1000 | H44: m3 | I44: 2023 | K44: 1 | L44: 2.6 | M44: =B44/G44 -> 0 | N44: =N$3/421.24 -> 0.95547906
A45: Agitator - Cl. Lj | C45: hp | D45: =D$180 -> 2 | E45: Stainless Steel, Fixed Propeller, 3 Impellers, 2 Blades, Motor, Gear drive | F45: =Inputs!F$849*G45 -> 600 | G45: 1 | H45: hp | I45: 1998 | J45: 4 | K45: 0.5 | L45: 1.5 | M45: =B45/G45 -> 0 | N45: =N$3/142.2 -> 2.8304219
A46: Feed Pump - E. Coli | C46: kg/hr | E46: 316 Stainless Steel | F46: 11358 | G46: 43149 | H46: kg/hr | I46: 2018 | K46: 0.8 | L46: 2.3 | M46: =B46/G46 -> 0 | N46: =N$3/329.7 -> 1.2207643
A47: Tank Wall - E. Coli | C47: m3 | D47: =CostCalc!D$289 -> 4 | E47: Concrete | F47: =Inputs!F$847 -> 188.34 | G47: 0.76 | H47: m3 | I47: 2022 | J47: 2 | K47: 0.7 | L47: 2.6 | M47: =B47/G47 -> 0 | N47: =N$3/432.15 -> 0.93135717
...

Sheet OPEX
A1: OPERATIONAL EXPENSE
A4: Transportation
A7: Variable Operating Cost
A8: Input | B8: Value Required | C8: Units | D8: Researched Values | H8: Scaled Cost
D9: Cost | E9: Units | F9: Year | G9: Source | H9: PPI 2024 | I9: Total Cost (per year)
A10: Diesel - Waste | B10: =CostCalc!B56 -> 355555.56 | C10: gal/yr | D10: 3.65 | E10: gal | F10: 2024 | H10: =CAPEX!N$3/389.544 -> 1.0332235 | I10: =B10*D10*H10 -> 1340894.4
A11: Diesel - Cheese Whey | B11: =CostCalc!B55 -> 355555.56 | C11: gal/yr | D11: 3.65 | E11: gal | F11: 2024 | H11: =CAPEX!N$3/389.544 -> 1.0332235 | I11: =B11*D11*H11 -> 1340894.4
A12: Diesel - Ocean Water | B12: =CostCalc!B54 -> 711111.11 | C12: gal/yr | D12: 3.65 | E12: gal | F12: 2024 | H12: =CAPEX!N$3/389.544 -> 1.0332235 | I12: =B12*D12*H12 -> 2681788.9
A13: Total: | I13: =SUM(I10:I12) -> 5363577.8
A15: Fixed Operational Cost: Labor
A16: Position | B16: Number Required | C16: Units | D16: 2024 Salary | E16: Total Cost (per year)
A17: Manager | B17: 3 | C17: person | D17: 100000 | E17: =D17*B17 -> 300000
A18: Operator | B18: 5 | C18: person | D18: 75000 | E18: =D18*B18 -> 375000
A19: Driver | B19: 200 | C19: person | D19: 65000 | E19: =D19*B19 -> 13000000
A20: Total: | E20: =SUM(E17:E19) -> 13675000
A24: Inoculum Development
A27: Variable Operating Cost
A28: Input | B28: Value Required | C28: Units | D28: Researched Values | H28: Scaled Cost
D29: Cost | E29: Units | F29: Year | G29: Source | H29: PPI 2024 | I29: Total Cost (per year)
A30: Pump Power - Cumulative | D30: 0.178 | E30: kWh | F30: 2024 | H30: =CAPEX!N$3/389.544 -> 1.0332235
A31: Mixing Power - Cumulative | D31: 0.178 | E31: kWh | F31: 2024 | H31: =CAPEX!N$3/389.544 -> 1.0332235
A32: Heat - Cumulative | D32: 0.178 | E32: kWh | F32: 2024 | H32: =CAPEX!N$3/389.544 -> 1.0332235
A33: Culture Broth - Caprociproducens
A34: Acetate | D34: 430 | E34: MT | F34: 2024 | H34: =CAPEX!N$3/389.544 -> 1.0332235
A35: Yeast Extract | D35: =2330/5 -> 466 | E35: kg (5 kg) | F35: 2024 | H35: =CAPEX!N$3/389.544 -> 1.0332235
A36: Trace Minerals - KH2PO4 | D36: =1815.37/25 -> 72.6148 | E36: kg (25 kg) | F36: 2024 | H36: =CAPEX!N$3/389.544 -> 1.0332235
A37: Trace Minerals - MgSO4 | D37: 318.5 | E37: kg | F37: 2024 | H37: =CAPEX!N$3/389.544 -> 1.0332235
A38: Trace Minerals - NaHCO3 | D38: 35.65 | E38: lb | F38: 2024 | H38: =CAPEX!N$3/389.544 -> 1.0332235
A39: Phosphate Buffer | D39: =130/2.5 -> 52 | E39: L (2.5 L) | F39: 2024 | H39: =CAPEX!N$3/389.544 -> 1.0332235
A40: Culture Broth - Lignocellulose
A41: Cellulose | D41: =595.65/10000 -> 0.059565 | E41: g (10 kg) | F41: 2024 | H41: =CAPEX!N$3/389.544 -> 1.0332235
A42: Yeast Extract | D42: =2330/5 -> 466 | E42: kg (5 kg) | F42: 2024 | H42: =CAPEX!N$3/389.544 -> 1.0332235
A43: Phosphate Buffer | D43: =130/2.5 -> 52 | E43: L (2.5 L) | F43: 2024 | H43: =CAPEX!N$3/389.544 -> 1.0332235
A44: Culture Broth - Clostridium
A45: Glucose | D45: 106 | E45: kg | H45: =CAPEX!N$3/389.544 -> 1.0332235
A46: Yeast Extract | D46: =2330/5 -> 466 | E46: kg (5kg) | F46: 2024 | H46: =CAPEX!N$3/389.544 -> 1.0332235
A47: Trace Minerals - KH2PO4 | D47: =1815.37/25 -> 72.6148 | E47: kg (25 kg) | F47: 2024 | H47: =CAPEX!N$3/389.544 -> 1.0332235
A48: Trace Minerals - MgSO4 | D48: 318.5 | E48: kg | F48: 2024 | H48: =CAPEX!N$3/389.544 -> 1.0332235
A49: Trace Minerals - NaCl | D49: =238/5 -> 47.6 | E49: kg (5 kg) | F49: 2024 | H49: =CAPEX!N$3/389.544 -> 1.0332235
A50: Phosphate Buffer | D50: =130/2.5 -> 52 | E50: L (2.5 L) | F50: 2024 | H50: =CAPEX!N$3/389.544 -> 1.0332235
...

Sheet Figures
A1: Transportation
B3: Capital Costs | C3: Operational Costs
A4: Boats - Ocean Water | B4: =CAPEX!O11 -> 40000000
A5: Diesel Trucks - Ocean Water | B5: =CAPEX!O12 -> 14555000
A6: Diesel Trucks - Cheese Whey | B6: =CAPEX!O13 -> 12425000
A7: Diesel Trucks - Organic Waste | B7: =CAPEX!O14 -> 15265000
A8: Hydraulic Truck Dump with Scale | B8: =CAPEX!O15 -> 17889360
A9: Diesel - Waste | C9: =OPEX!I10 -> 1340894.4
A10: Diesel - Lactate Concentrate | C10: =OPEX!I11 -> 1340894.4
A11: Diesel - Ocean Water | C11: =OPEX!I12 -> 2681788.9
A12: Labor | C12: =OPEX!E20 -> 13675000
A32: Ocean Water Processing
A34: Equipment Name | B34: Capital Costs | C34: Operational Costs
A35: Feed Pump | B35: =CAPEX!O62 -> 52655.972
A36: Decanter | B36: =CAPEX!O63 -> 3588586.4
A37: Microfiltration | B37: =CAPEX!O64 -> 3774.8245
A38: Anion-Exchange Membrane | B38: =CAPEX!O65 -> 14013.8
A39: Cation-Exchange Membrane | B39: =CAPEX!O66 -> 15327.594
A40: Bipolar-Exchange Membranes | B40: =CAPEX!O67 -> 65029.473
A41: Electrodes | B41: =CAPEX!O68 -> 173415.16
A42: Diluate Tanks | B42: =CAPEX!O69 -> 23242.011
A43: Electrolyte Tank Wall | B43: =CAPEX!O70 -> 6000.882
A44: Concentrate Tank 1 Wall | B44: =CAPEX!O71 -> 6000.882
A45: Concentrate Tank 2 Wall | B45: =CAPEX!O72 -> 6000.882
A46: Peristaltic Pump | B46: =CAPEX!O73 -> 242949.56
... A52: Desalinated Water Storage Tank | B52: =CAPEX!O79 -> 239743.36
A53: Power - Feed Pump | C53: =OPEX!I69 -> 2801.3359
A54: Power - Acid Pump | C54: =OPEX!I70 -> 327.64623
A55: Power - Base Pump | C55: =OPEX!I71 -> 327.64623
A56: Power - Electrolyte Pump | C56: =OPEX!I72 -> 327.64623
A57: Heat - Crystallizer | C57: =OPEX!I73 -> 0
A58: Power - Applied Voltage | C58: =OPEX!I74 -> 79945.112
A59: Labor | C59: =OPEX!E84 -> 855000
A63: Cheese Whey Processing
B65: Capital Costs | C65: Operational Costs
A66: Feed Pump - CW+H2O | B66: =CAPEX!O91 -> 23020.811
A67: Feed Pump - Recycle | B67: =CAPEX!O92 -> 8786.5345
A68: Hydrolysis Tank Wall | B68: =CAPEX!O93 -> 35026.318
A69: Hydrolysis Insulation | B69: =CAPEX!O94 -> 168558.98
A70: Hydrolysis Agitator | B70: =CAPEX!O95 -> 31865.127
...

Sheet A_DCFROR
B2: Economic Inputs | G2: Net Present Values
H3: Portion of MFSP | I3: Expenses | J3: Fraction of Cost
B4: Capital and Operational Costs | G4: Operating Costs | H4: =$D$41*J4 -> 0.85774367 | I4: =D92 -> 6.4211628e+08 | J4: =I4/$I$8 -> 0.71478639
B5: Operational cost | D5: =OPEX!$B$684 -> 69797966 | G5: Equipment and Facilities | H5: =$D$41*J5 -> 0.24812157 | I5: =D93 -> 1.8574652e+08 | J5: =I5/$I$8 -> 0.20676798
B6: Equipment and facilities capital cost | D6: =CAPEX!$B$560 -> 3.8826614e+08 | G6: Taxes | H6: =$D$41*J6 -> 0 | I6: =D91 -> 0 | J6: =I6/$I$8 -> 0
B7: Land capital cost | D7: =D6*0.15 -> 58239921 | G7: Land | H7: =$D$41*J7 -> 0.094134753 | I7: =D89 -> 70470304 | J7: =I7/$I$8 -> 0.078445627
B8: Working capital | D8: =D6*0.05 -> 19413307 | G8: Total | H8: =SUM(H4:H7) -> 1.2 | I8: =SUM(I4:I7) -> 8.983331e+08 | J8: =SUM(J4:J7) -> 1
B10: Loan | G10: Mass Allocation
B11: Equity | D11: 0.4 | G11: Total Product | H11: =SUM(D29:D32) -> 6877297.3 | I11: kg/hr
B12: Loan interest | D12: 0.08 | G12: =B29 -> >90% Ammonia Sulfate | H12: =D29/H$11 -> 0.061950413
B13: Loan term | D13: 10 | G13: =B30 -> >90% Magnesium Sulfate | H13: =D30/H$11 -> 0.026679039
B14: Annual loan payment | D14: =-PMT(D12,D13,D6*(1-D11)) -> 34717862 | G14: =B31 -> Jet Fuel | H14: =D31/H$11 -> 0.89361163
G15: =B32 -> Naphtha | H15: =D32/H$11 -> 0.017758914
B16: Depreciation
B17: MACRS | C17: Years | D17: 7
B19: Construction Period
B20: Construciton period (years) | D20: 3
C21: % yr -2 | D21: 0.1
C22: % yr -1 | D22: 0.5
C23: % yr 0 | D23: 0.4
B25: Productivity
B26: Start up time | C26: Years | D26: 0.5
B27: Start up production | C27: % of full production | D27: 0.5
B29: >90% Ammonia Sulfate | C29: kg/yr | D29: =SUM(ExpBase!$D$623:$D$635)*Inputs!$F$3 -> 426051.41
B30: >90% Magnesium Sulfate | C30: kg/yr | D30: =SUM(ExpBase!$C$623:$C$635)*Inputs!$F$3 -> 183479.68
B31: Jet Fuel | C31: kg/yr | D31: =ExpBase!$C$1151*Inputs!$F$3/1.02 -> 6145632.9
B32: Naphtha | C32: kg/yr | D32: =ExpBase!$C$1150*Inputs!$F$3/1.02 -> 122133.33
B33: Waste Collection | C33: kg/yr | D33: =(ExpBase!$G$126+Inputs!$F$13)*Inputs!$F$3 -> 2.2414277e+08
B35: Internal Rate of Return and Tax Rate
B36: Internal rate of return | D36: 0.1
B37: Tax rate | D37: 0.35
B39: Results
B41: >90% Ammonia Sulfate | C41: per kg | D41: 1.2
B42: >90% Magnesium Sulfate | C42: per kg | D42: 2
B43: MSP Jet Fuel | C43: per kg | D43: 7.33
B44: Naphtha | C44: per kg | D44: 0.85
B45: Waste Collection | C45: per kg | D45: 0.05
B47: Net Present Value | D47: =D86-SUM(E87:G87) -> -6.1829465e+08
B49: Cash flow analysis
B51: Year | E51: -2 | F51: -1 | G51: 0 | H51: 1 | I51: 2 | J51: 3 | K51: 4 | L51: 5 | M51: 6 | N51: 7 | O51: 8 | P51: 9 | Q51: 10 | R51: 11 | S51: 12 | T51: 13 | U51: 14 | V51: 15 | W51: 16 | X51: 17 | Y51: 18 | Z51: 19 | AA51: 20 | AB51: 21 | AC51: 22 | AD51: 23 | AE51: 24 | AF51: 25 | AG51: 26 | AH51: 27 | AI51: 28 | AJ51: 29 | AK51: 30
...

Sheet B_DCFROR
B2: Economic Inputs | G2: NET PRESENT VALUES
H3: Portion of MFSP | I3: Expenses | J3: Fraction of Cost
B4: Capital and Operational Costs | G4: Operating Costs | H4: =$D$41*J4 -> 0.17315874 | I4: =D92 -> 1.298982e+09 | J4: =I4/$I$8 -> 0.4556809
B5: Operational cost | D5: =SUM(OPEX!$B$694:$B$711) -> 1.4119919e+08 | G5: Equipment and Facilities | H5: =$D$41*J5 -> 0.13340044 | I5: =D93 -> 1.0007278e+09 | J5: =I5/$I$8 -> 0.35105378
B6: Equipment and facilities capital cost | D6: =SUM(CAPEX!$B$578:$B$592) -> 2.0918223e+09 | G6: Taxes | H6: =$D$41*J6 -> 0.022830081 | I6: =D91 -> 1.7126403e+08 | J6: =I6/$I$8 -> 0.060079161
B7: Land capital cost | D7: =D6*0.15 -> 3.1377334e+08 | G7: Land | H7: =$D$41*J7 -> 0.050610742 | I7: =D89 -> 3.7966574e+08 | J7: =I7/$I$8 -> 0.13318616
B8: Working capital | D8: =D6*0.05 -> 1.0459111e+08 | G8: Total | H8: =SUM(H4:H7) -> 0.38 | I8: =SUM(I4:I7) -> 2.8506395e+09 | J8: =SUM(J4:J7) -> 1
B10: Loan
B11: Equity | D11: 0.4
B12: Loan interest | D12: 0.08
B13: Loan term | D13: 10
B14: Annual loan payment | D14: =-PMT(D12,D13,D6*(1-D11)) -> 1.8704592e+08 | G14: Mass Allocation
G15: Total Product | H15: =SUM(D29:D32) -> 2601831.8 | I15: kg/hr
B16: Depreciation | G16: =B29 -> >90% Ammonia Sulfate | H16: =D29/H$15 -> 0.16375056
B17: MACRS | C17: Years | D17: 7 | G17: =B30 -> >90% Magnesium Sulfate | H17: =D30/H$15 -> 0.070519424
G18: =B31 -> Pentyl Caproate | H18: =D31/H$15 -> 0.19550254
B19: Construction Period | G19: =B32 -> Other Pure Esters | H19: =D32/H$15 -> 0.57022748
B20: Construciton period (years) | D20: 3
C21: % yr -2 | D21: 0.1
C22: % yr -1 | D22: 0.5
C23: % yr 0 | D23: 0.4
B25: Productivity
B26: Start up time | C26: Years | D26: 0.5
B27: Start up production | C27: % of full production | D27: 0.5
B29: >90% Ammonia Sulfate | C29: kg/yr | D29: =A_DCFROR!D29 -> 426051.41
B30: >90% Magnesium Sulfate | C30: kg/yr | D30: =A_DCFROR!D30 -> 183479.68
B31: Pentyl Caproate | C31: kg/yr | D31: =ExpBase!$B$2000*Inputs!$F$3 -> 508664.73
B32: Other Pure Esters | C32: kg/yr | D32: =(ExpBase!$B$2009-ExpBase!$B$2000)*Inputs!F3 -> 1483636
B33: Waste Collection | C33: kg/yr | D33: =A_DCFROR!D33 -> 2.2414277e+08
B35: Internal Rate of Return and Tax Rate
B36: Internal rate of return | D36: 0.1
B37: Tax rate | D37: 0.35
B39: Results
B41: >90% Ammonia Sulfate | C41: per kg | D41: 0.38
B42: >90% Magnesium Sulfate | C42: per kg | D42: 1.5
B43: MSP Pentyl Caproate | C43: per kg | D43: 756.75
B44: Other Pure Esters | C44: per kg | D44: 15
B45: Waste Collection | C45: per kg | D45: 0.01
B47: Net Present Value | D47: =D86-SUM(E87:G87) -> -4.081692e+08
B49: Cash flow analysis
...

Sheet AB_DCFROR
B2: Economic Inputs | G2: NET PRESENT VALUES
H3: Portion of MFSP | I3: Expenses | J3: Fraction of Cost
B4: Capital and Operational Costs | G4: Operating Costs | H4: =$D$43*J4 -> 0.24414907 | I4: =D99 -> 1.9410983e+09 | J4: =I4/$I$8 -> 0.54255348
B5: Operational cost | D5: =A_DCFROR!D5+B_DCFROR!D5 -> 2.1099716e+08 | G5: Equipment and Facilities | H5: =$D$43*J5 -> 0.14923335 | I5: =D100 -> 1.1864743e+09 | J5: =I5/$I$8 -> 0.33162966
B6: Equipment and facilities capital cost | D6: =A_DCFROR!D6+B_DCFROR!D6 -> 2.4800884e+09 | G6: Taxes | H6: =$D$43*J6 -> 0 | I6: =D98 -> 0 | J6: =I6/$I$8 -> 0
B7: Land capital cost | D7: =D6*0.15 -> 3.7201326e+08 | G7: Land | H7: =$D$43*J7 -> 0.056617585 | I7: =D96 -> 4.5013605e+08 | J7: =I7/$I$8 -> 0.12581686
B8: Working capital | D8: =D6*0.05 -> 1.2400442e+08 | G8: Total | H8: =SUM(H4:H7) -> 0.45 | I8: =SUM(I4:I7) -> 3.5777086e+09 | J8: =SUM(J4:J7) -> 1
B10: Loan | G10: Mass Allocation
B11: Equity | D11: 0.4 | G11: Total Product | H11: =SUM(D29:D32) -> 7486828.4 | I11: kg/hr
B12: Loan interest | D12: 0.08 | G12: =B29 -> >90% Ammonia Sulfate | H12: =D29/H$11 -> 0.11381359
B13: Loan term | D13: 10 | G13: =B30 -> >90% Magnesium Sulfate | H13: =D30/H$11 -> 0.049013994
B14: Annual loan payment | D14: =-PMT(D12,D13,D6*(1-D11)) -> 2.2176378e+08 | G14: =B31 -> Jet Fuel (Hydrocarbon C8-C16) | H14: =D31/H$11 -> 0.82085932
G15: =B32 -> Naphtha (Hydrocarbon <C8) | H15: =D32/H$11 -> 0.016313093
B16: Depreciation
B17: MACRS | C17: Years | D17: 7
B19: Construction Period
B20: Construciton period (years) | D20: 3
C21: % yr -2 | D21: 0.1
C22: % yr -1 | D22: 0.5
C23: % yr 0 | D23: 0.4
B25: Productivity
B26: Start up time | C26: Years | D26: 0.5
B27: Start up production | C27: % of full production | D27: 0.5
B29: >90% Ammonia Sulfate | C29: kg/yr | D29: =SUM(A_DCFROR!D29+B_DCFROR!D29) -> 852102.83
B30: >90% Magnesium Sulfate | C30: kg/yr | D30: =SUM(A_DCFROR!D30,B_DCFROR!D30) -> 366959.36
B31: Jet Fuel (Hydrocarbon C8-C16) | C31: kg/yr | D31: =ExpBase!$C$1151*Inputs!$F$3/1.02 -> 6145632.9
B32: Naphtha (Hydrocarbon <C8) | C32: kg/yr | D32: =ExpBase!$C$1150*Inputs!$F$3/1.02 -> 122133.33
B33: Pentyl Caproate | C33: kg/yr | D33: =B_DCFROR!D31 -> 508664.73
B34: Other Pure Esters | C34: kg/yr | D34: =B_DCFROR!D32 -> 1483636
B35: Waste Collection | C35: kg/yr | D35: =(A_DCFROR!D33+B_DCFROR!D33) -> 4.4828554e+08
B37: Internal Rate of Return and Tax Rate
B38: Internal rate of return | D38: 0.1
B39: Tax rate | D39: 0.35
B41: Results
B43: >90% Ammonia Sulfate | C43: per kg | D43: 0.45
B44: >90% Magnesium Sulfate | C44: per kg | D44: 1.8
B45: MSP Jet Fuel | C45: per kg | D45: 0.8
B46: Naphtha | C46: per kg | D46: 0.65
B47: Pentyl Caproate | C47: per kg | D47: 180
B48: Other Pure Esters | C48: per kg | D48: 145
...

Sheet Scale&MVA
A1: ECONOMIES OF SCALE FIGURE
A2: SCALE | B2: Path A - Jet Only | C2: Path AB - Jet & Esters | D2: A | E2: AB
A3: ton/yr
A4: =ROUNDUP(482812,5) -> 482812 | B4: 35.877437 | C4: 95.598886 | D4: =B4 -> 35.877437 | E4: =C4 -> 95.598886
A5: 724218 | B5: 29.470752 | C5: 44.902507 | D5: =B5 -> 29.470752 | E5: =C5 -> 44.902507
A6: 965624 | B6: 26.072423 | C6: 19.916435 | D6: =B6 -> 26.072423 | E6: =C6 -> 19.916435
A7: 1448437 | B7: 22.395543 | C7: -7.6601671 | D7: 24.679666 | E7: =C7 -> -7.6601671
A8: 1931249 | B8: 20.417827 | C8: -23.286908 | D8: =B8 -> 20.417827 | E8: =C8 -> -23.286908
A49: Market Value Analysis Figure
B51: Caproic Acid | C51: Pentanol | D51: Hexanol | E51: Ethyl Caproate | F51: Pentyl Caproate | G51: Hexyl Caproate | H51: Triethanolamine
A52: Kilograms | B52: USD | C52: USD | D52: USD | E52: USD | F52: USD | G52: USD | H52: USD | J52: Market Value: | K52: 1 MT [USD] | L52: 1 kg [USD]
A53: 1 | B53: 205 | C53: 169 | D53: 168 | E53: 171 | F53: 198 | G53: 210 | H53: 220 | J53: Caproic Acid * | K53: =ROUNDUP(B62,2)*1000 -> 8950 | L53: =B53 -> 205
A54: 5 | B54: 55 | C54: 44 | D54: 43 | E54: 48 | F54: 73 | G54: 85 | H54: 70 | J54: Pentanol * | K54: =ROUNDUP(C62,1)*1000 -> 4100 | L54: =C53 -> 169
A55: 10 | B55: 35 | C55: 24 | D55: 23 | E55: 26 | F55: 53 | G55: 65 | H55: 34 | J55: Hexanol | K55: =ROUNDUP(D62,2)*1000 -> 3490 | L55: =D53 -> 168
A56: 50 | B56: 29 | C56: 18 | D56: 17 | E56: 20 | F56: 47 | G56: 59 | H56: 24 | J56: Ethyl Caproate | K56: =ROUNDUP(E62,2)*1000 -> 5010 | L56: =E53 -> 171
A57: 160 | D57: 11 | J57: Pentyl Caproate * | K57: =ROUNDUP(F62,2)*1000 -> 20350 | L57: =F53 -> 198
A58: 170 | C58: 12 | J58: Hexyl Caproate | K58: =ROUNDUP(G62,1)*1000 -> 28600 | L58: =G53 -> 210
A59: 180 | B59: 23 | E59: 14 | F59: 41 | G59: 53 | J59: Triethanolamine | K59: =158.68*(1000)^(-0.469)*1000 -> 6216.1601 | L59: 220
A60: 230 | H60: 16 | J60: Jet Fuel | K60: =88.3/7.46 -> 11.836461 | L60: =2.05/3.79 -> 0.5408971
J61: Diesel Fuel | K61: =180/7.46 -> 24.128686 | L61: =4.5/3.79 -> 1.1873351
A62: 1000 | B62: =134.16*(A62^(-0.392)) -> 8.9458796 | C62: =116.54*A62^(-0.488) -> 4.0038243 | D62: =117.18*A62^(-0.509) -> 3.4821983 | E62: =118.44*A62^(-0.458) -> 5.0060871 | F62: =141.72*A62^(-0.281) -> 20.343756 | G62: =154.2*1000^(-0.244) -> 28.581458

Sheet BM_Flow
A1: STANDARD ANAEROBIC DIGESTION FOR METHANE PRODUCTION
A2: Biogas Production
A3: Parameter | B3: Unit | C3: Value | D3: Unit | E3: Value
A4: Specific Methane Yield of Sewage Sludge | B4: mL CH4 / g VS | C4: 0.07
A5: Specific Methane Yield of Plant Matter | B5: mL CH4 / g VS | C5: 0.3
A6: Specific Methane Yield of Cattle Manure | B6: mL CH4 / g VS | C6: 0.094
A7: Specific Methane Yield of Swine Manure | B7: mL CH4 / g VS | C7: 0.13
A8: Specific Methane Yield of Dairy Manure | B8: mL CH4 / g VS | C8: 0.24
A9: Specific Methane Yield of Co-Digested Food Grease | B9: mL CH4 / g VS | C9: =810.7/1000 -> 0.8107
A10: Specific Methane Yield of Co-Digestated Food Waste 1 | B10: mL CH4 / g VS | C10: =289/1000 -> 0.289
A11: Specific Methane Yield of Co-Digestated Food Waste 2 | B11: mL CH4 / g VS | C11: =241/1000 -> 0.241
A12: Specific Methane Yield of Co-Digestated Food Waste 3 | B12: mL CH4 / g VS | C12: =287.7/1000 -> 0.2877
A13: Specific Methane Yield of Co-Digestated Food Processing Waste 1 | B13: mL CH4 / g VS | C13: =537.8/1000 -> 0.5378
A14: Specific Methane Yield of Co-Digestated Food Processing Waste 2 | B14: mL CH4 / g VS | C14: =237.8/1000 -> 0.2378
A15: Volatile Solids in Manure | B15: g VS/g | C15: =ExpBase!C230 -> 0.20761053
A16: Volatile Solids in Food Waste | B16: g VS/g | C16: =ExpBase!C231 -> 0.3996 | G16: Figure
A17: Total Volatile Solids Influent Flow Rate | B17: g VS /hr | C17: =((Inputs!F13*Inputs!F14*C16)+(Inputs!F13*Inputs!F15*C15))*1000 -> 5670236.8 | H17: L/hr | I17: L/ g VS
A18: Expected Methane Yield Based on Feedstock | B18: L CH4 / g VS | C18: =((AVERAGE(C6,C8)*Inputs!F15*Inputs!F16)+(C7*Inputs!F15*Inputs!F17)+(AVERAGE(C10:C14)*Inputs!F14))/1000 -> 0.000168846 | G18: Total Methane Flow Rate | H18: =C28 -> 957.39681 | I18: =H18/(C$17/1000) -> 0.168846
A19: Total Methane Flow Rate | B19: L CH4 / hr | C19: =C17*C18 -> 957.39681 | G19: Total Carbon Dioxide Flow Rate | H19: =C29 -> 509.58217 | I19: =H19/(C$17/1000) -> 0.089869645
A20: H2S Concentration in Biogas | B20: mg/m3 | C20: 10000 | G20: Total Nitrogen Flow Rate | H20: =C30 -> 77.20942 | I20: =H20/(C$17/1000) -> 0.013616613
A21: Ammonia Concentration in Biogas | B21: mg/m3 | C21: 100 | G21: Hydrogen Sulfide Flow Rate | H21: =C31 -> 17.344942 | I21: =H21/(C$17/1000) -> 0.0030589449
A22: Total Chlorine Concentration in Biogas | B22: mg/m3 | C22: 100
A23: Total Fluorine Concentration in Biogas | B23: mg/m3 | C23: 100 | H23: L/ g VS
A24: Percent Methane in Biogas | B24: %/100 | C24: 0.62 | G24: Methane Yield | H24: 0.168846
A25: Percent Carbon Dioxide in Biogas | B25: %/100 | C25: 0.33 | G25: Carbon Dioxide Yield | H25: 0.089869645
A26: Percent Nitrogen in Biogas | B26: %/100 | C26: 0.05 | G26: Nitrogen Yield | H26: 0.013616613
A27: Total Main Biogas Flow Rate | B27: L/hr | C27: =C17*C18/C24 -> 1544.1884 | D27: m3/hr | E27: =SUM(E28:E30) -> 1734.4942 | F27: ton C/hr | G27: Hydrogen Sulfide Yield | H27: 0.0030589449
A28: Total Methane Flow Rate | B28: L/hr | C28: =C$27*C24 -> 957.39681 | D28: m3/hr | E28: =C28*Units!C29 -> 629.0097 | F28: 0.8783 | G28: Total Flow Rate | H28: =SUM(H18:H21) -> 1561.5333
A29: Total Carbon Dioxide Flow Rate | B29: L/hr | C29: =C$27*C25 -> 509.58217 | D29: m3/hr | E29: =C29*Units!C30 -> 1008.9727
A30: Total Nitrogen Flow Rate | B30: L/hr | C30: =C$27*C26 -> 77.20942 | D30: m3/hr | E30: =C30*Units!C32 -> 96.511775
A31: Hydrogen Sulfide Flow Rate | B31: kg/hr | C31: =E$27*C20*Units!C$80 -> 17.344942 | D31: m3/hr | E31: =C31*Units!C33 -> 23.589121
A32: Ammonia Flow Rate | B32: kg/hr | C32: =E$27*C21*Units!C$80 -> 0.17344942
A33: Total Chlorine Flow Rate | B33: kg/hr | C33: =E$27*C22*Units!C$80 -> 0.17344942
A34: Total Fluorine Flow Rate | B34: kg/hr | C34: =E$27*C23*Units!C$80 -> 0.17344942
A35: TOTAL Biogas Flow Rate | B35: m3/hr | C35: =SUM(E27:E31)^0.95 -> 2322.6766 | D35: =C35*0.15 -> 348.40149 | E35: emissions of stabilized sludge
A38: Methane Production
A39: Parameter | B39: Unit | C39: Value
A40: Researched Water Scrubber Parameters
A41: Electricity Demand | B41: kWh/m3 BG | C41: 0.25
A42: Operation Pressure | B42: bar | C42: 6
...

Sheet BM_CAPEX
A1: CAPITAL EXPENSE - BIOMETHANE
A4: Feedstock Transportation
A6: Total Capital Investment
A7: Mechanical Equipment List | F7: Researched Values | K7: Scaled Installed in Current Year Factors | O7: Total Cost
A8: Equipment Name | B8: Size | C8: Unit | D8: Number Required | E8: Material | F8: Cost | G8: Size | H8: Unit | I8: Year | J8: Source | K8: Scaling Exponent | L8: Installation Factor | M8: Size Ratio | N8: PPI 2024
A10: Diesel Trucks | B10: =CAPEX!B14*2 -> 80 | C10: yd3 | D10: =CAPEX!D14 -> 43 | E10: Peterbilt Front Loader | F10: =Inputs!F$844*G10 -> 355000 | G10: 40 | H10: yd3 | I10: 2024 | K10: 1 | L10: 1 | M10: =B10/G10 -> 2 | N10: =CAPEX!N13 -> 1 | O10: =N10*F10*D10*M10 -> 30530000
A11: Hydraulic Truck Dump with Scale | B11: =CAPEX!B15*2 -> 74603.186 | C11: lb/hr | D11: 2 | F11: 80000 | G11: 367.437 | H11: lb/hr | I11: 1998 | K11: 0.6 | L11: 2.47 | M11: =B11/G11 -> 203.03667 | N11: =CAPEX!N15 -> 2.8304219 | O11: =D11*N11*F11*L11*M11^(K11) -> 27115200
A12: Total: | O12: =SUM(O10:O11) -> 57645200
A15: Feedstock Preparation
A17: Mechanical Equipment List | F17: Researched Values | K17: Scaled Installed in Current Year Factors | O17: Total Cost
A18: Equipment Name | B18: Size | C18: Unit | D18: Number Required | E18: Material | F18: Cost | G18: Size | H18: Unit | I18: Year | J18: Source | K18: Scaling Exponent | L18: Installation Factor | M18: Size Ratio | N18: PPI
N19: 2024
A20: Sand Removal - Manure | B20: =CAPEX!B121*2 -> 22306 | C20: cow | D20: 2 | E20: 20'' by 22' Sand-Manure Separtor, 5 hp electric motor | F20: 33000 | G20: 75 | H20: cow | I20: 2003 | K20: 0.9 | L20: 1.5 | M20: =B20/G20 -> 297.41333 | N20: =CAPEX!N121 -> 2.5983602 | O20: =D20*N20*F20*L20*M20^(K20) -> 43287145
A21: Tank Wall - Manure | B21: =CAPEX!B122*2 -> 9.7684828 | C21: m3 | D21: 2 | E21: Concrete | F21: =Inputs!F$847 -> 188.34 | G21: 0.76 | H21: m3 | I21: 2022 | J21: 6 | K21: 0.7 | L21: 1.8 | M21: =B21/G21 -> 12.853267 | N21: =CAPEX!N122 -> 0.93135717 | O21: =D21*N21*F21*L21*M21^(K21) -> 3772.8609
A22: Insulation - Manure | B22: =CAPEX!B123*2 -> 19.536966 | C22: m2 | D22: 2 | E22: Unfaced Fiberglass | F22: =CostCalc!F$714 -> 8.35 | G22: =ROUNDUP(CostCalc!G$714,2) -> 0.1 | H22: m2 | I22: 2022 | J22: 3 | K22: 0.7 | L22: 1.5 | M22: =B22/G22 -> 195.36966 | N22: =CAPEX!N123 -> 0.93135717 | O22: =D22*N22*F22*L22*M22^(K22) -> 936.53491
A23: Agitator - Manure | B23: =CAPEX!B124*2 -> 448.69991 | C23: hp | D23: 2 | E23: 304 Stainless Steel, Fixed Propeller, 3 Impellers, 2 Blades, Motor, Gear drive | F23: 52500 | G23: 30 | H23: hp | I23: 2009 | K23: 1 | L23: 1.5 | M23: =B23/G23 -> 14.956664 | N23: =CAPEX!N124 -> 1.4716124 | O23: =D23*N23*F23*L23*M23^(K23) -> 3466639.9
A24: Tank Wall - Food Waste | B24: =CAPEX!B125*2 -> 3.8338232 | C24: m3 | D24: 2 | E24: Concrete | F24: =Inputs!F$847 -> 188.34 | G24: 0.76 | H24: m3 | I24: 2022 | J24: 6 | K24: 0.7 | L24: 1.8 | M24: =B24/G24 -> 5.0445043 | N24: =CAPEX!N125 -> 0.93135717 | O24: =D24*N24*F24*L24*M24^(K24) -> 1960.353
A25: Insulation - Food Waste | B25: =CAPEX!B126*2 -> 7.6676465 | C25: m2 | D25: 2 | E25: Unfaced Fiberglass | F25: =CostCalc!F$714 -> 8.35 | G25: =ROUNDUP(CostCalc!G$714,2) -> 0.1 | H25: m2 | I25: 2022 | J25: 3 | K25: 0.7 | L25: 1.5 | M25: =B25/G25 -> 76.676465 | N25: =CAPEX!N126 -> 0.93135717 | O25: =D25*N25*F25*L25*M25^(K25) -> 486.61719
A26: Agitator - Food Waste | B26: =CAPEX!B127*2 -> 49.855546 | C26: hp | D26: 2 | E26: 304 Stainless Steel, Fixed Propeller, 3 Impellers, 2 Blades, Motor, Gear drive | F26: 52500 | G26: 30 | H26: hp | I26: 2009 | K26: 1 | L26: 1.5 | M26: =B26/G26 -> 1.6618515 | N26: =CAPEX!N127 -> 1.4716124 | O26: =D26*N26*F26*L26*M26^(K26) -> 385182.22
A27: Feed Pump - Manure | B27: =CAPEX!B128*2 -> 2838.75 | C27: GPM | D27: 2 | E27: Concentrated wastewater pump | F27: 4900 | G27: 7 | H27: GPM | I27: 2013 | K27: 0.8 | L27: 4.31 | M27: =B27/G27 -> 405.53571 | N27: =CAPEX!N128 -> 1.3248387 | O27: =D27*N27*F27*L27*M27^(K27) -> 6827939.1
A28: Feed Pump - Food Waste | B28: =CAPEX!B129*2 -> 315.41667 | C28: GPM | D28: 2 | E28: Concentrated wastewater pump | F28: 4900 | G28: 7 | H28: GPM | I28: 2013 | K28: 0.8 | L28: 4.31 | M28: =B28/G28 -> 45.059524 | N28: =CAPEX!N129 -> 1.3248387 | O28: =D28*N28*F28*L28*M28^(K28) -> 1177323
A29: Feed Pump - Water | B29: =CAPEX!B130*2 -> 788.54167 | C29: GPM | D29: 2 | E29: Clean water pump | F29: 5200 | G29: 140 | H29: GPM | I29: 2013 | K29: 0.8 | L29: 4.31 | M29: =B29/G29 -> 5.6324405 | N29: =CAPEX!N130 -> 1.3248387 | O29: =D29*N29*F29*L29*M29^(K29) -> 236717.8
A30: Manure Slurry Pump Grinder | B30: =CAPEX!B131*2 -> 45000 | C30: kg/hr | D30: 2 | E30: Little Giant Pump | F30: =Inputs!F$845*G30 -> 1170 | G30: =CostCalc!G$237 -> 11700 | H30: kg/hr | I30: 2024 | J30: 1 | K30: 0.8 | L30: 2.3 | M30: =B30/G30 -> 3.8461538 | N30: =CAPEX!N131 -> 1.0332235 | O30: =D30*N30*F30*L30*M30^(K30) -> 16336.51
A31: Food Waste Slurry Pump Grinder | B31: =CAPEX!B132*2 -> 6250 | C31: kg/hr | D31: 2 | E31: Little Giant Pump | F31: =Inputs!F$845*G31 -> 1170 | G31: =CostCalc!G$237 -> 11700 | H31: kg/hr | I31: 2024 | J31: 1 | K31: 0.8 | L31: 2.3 | M31: =B31/G31 -> 0.53418803 | N31: =CAPEX!N132 -> 1.0332235 | O31: =D31*N31*F31*L31*M31^(K31) -> 3367.3889
A33: Total: | O33: =SUM(O20:O31) -> 55407808
A36: Anaerobic Digestion
A38: Total Capital Investment
A39: Mechanical Equipment List | F39: Researched Values | K39: Scaled Installed in Current Year Factors | O39: Total Cost
A40: Equipment Name | B40: Size | C40: Unit | D40: Number Required | E40: Material | F40: Cost | G40: Size | H40: Unit | I40: Year | J40: Source | K40: Scaling Exponent | L40: Installation Factor | M40: Size Ratio | N40: PPI
N41: 2023
A42: Feed Pump | B42: =(CAPEX!B176+CAPEX!B159)*2 -> 62500 | C42: kg/hr | D42: =CAPEX!D176 -> 2 | E42: 316 Stainless Steel | F42: 11358 | G42: 43149 | H42: kg/hr | I42: 2018 | K42: 0.8 | L42: 2.3 | M42: =B42/G42 -> 1.4484693 | N42: =CAPEX!N176 -> 1.2207643 | O42: =N42*L42*F42*D42*(M42)^K42 -> 85786.501
A43: Digester Tank Wall | B43: =(CAPEX!B179+CAPEX!B162)*2 -> 99283.052 | C43: m3 | D43: =CAPEX!D179 -> 2 | E43: Concrete | F43: =CAPEX!F179 -> 188.34 | G43: 0.76 | H43: m3 | I43: 2022 | J43: 2 | K43: 0.7 | L43: 2.6 | M43: =B43/G43 -> 130635.59 | N43: =CAPEX!N179 -> 0.93135717 | O43: =N43*L43*F43*D43*(M43)^K43 -> 3477805.1
A44: Digester Insulation | B44: =(CAPEX!B180+CAPEX!B163)*2 -> 10973.445 | C44: m2 | D44: =CAPEX!D180 -> 2 | E44: Unfaced Fiberglass | F44: =CAPEX!F180 -> 8.35 | G44: 0.09 | H44: m2 | I44: 2022 | J44: 3 | K44: 1 | L44: 2.6 | M44: =B44/G44 -> 121927.17 | N44: =CAPEX!N180 -> 0.93135717 | O44: =N44*D44*L44*F44*(M44^K44) -> 4930677.1
A45: Digester Gas Cover | B45: =(CAPEX!B181+CAPEX!B164)*2 -> 203.28032 | C45: m3 | D45: =CAPEX!D181 -> 2 | E45: Double Membrane Polyvinylidene Fluoride 1.5 mm, Pressure and Volume Sensor | F45: =CAPEX!F181 -> 32000.06 | G45: 1000 | H45: m3 | I45: 2023 | K45: 1 | L45: 2.6 | M45: =B45/G45 -> 0.20328032 | N45: =CAPEX!N181 -> 0.95547906 | O45: =N45*L45*F45*D45*M45^K45 -> 32319.948
A46: Agitator | B46: =(CAPEX!B182+CAPEX!B165)*2 -> 1266.3309 | C46: hp | D46: =CAPEX!D182 -> 2 | E46: Stainless Steel, Fixed Propeller, 3 Impellers, 2 Blades, Motor, Gear drive | F46: =CAPEX!F182 -> 52500 | G46: 30 | H46: hp | I46: 1998 | J46: 4 | K46: 0.5 | L46: 1.5 | M46: =B46/G46 -> 42.211029 | N46: =CAPEX!N182 -> 1.4716124 | O46: =D46*N46*F46*L46*(M46)^K46 -> 1505868.2
A47: Total: | O47: =SUM(O43:O46) -> 9946670.3
A50: Solid-Liquid Separation
A52: Mechanical Equipment List | F52: Researched Values | K52: Scaled Installed in Current Year Factors | O52: Total Cost
A53: Equipment Name | B53: Size | C53: Unit | D53: Number Required | E53: Material | F53: Cost | G53: Size | H53: Unit | I53: Year | J53: Source | K53: Scaling Exponent | L53: Installation Factor | M53: Size Ratio | N53: PPI
N54: 2024
...

Sheet BM_OPEX
A1: OPERATIONAL EXPENSE - BIOMETHANE
A5: Feedstock Transportation
A8: Variable Operating Cost
A9: Input | B9: Value Required | C9: Units | D9: Researched Values | H9: Scaled Cost
D10: Cost | E10: Units | F10: Year | G10: Source | H10: PPI 2024 | I10: Total Cost (per year)
A11: Diesel - Waste | B11: =OPEX!B10*2 -> 711111.11 | C11: gal/yr | D11: 3.65 | E11: gal | F11: 2024 | H11: =CAPEX!N$3/389.544 -> 1.0332235 | I11: =B11*D11*H11 -> 2681788.9
A12: Total: | I12: =SUM(I11:I11) -> 2681788.9
A14: Fixed Operational Cost: Labor
A15: Position | B15: Number Required | C15: Units | D15: 2024 Salary | E15: Total Cost (per year)
A16: Manager | B16: =ROUNDUP(OPEX!B17/3,0) -> 1 | C16: person | D16: 100000 | E16: =D16*B16 -> 100000
A17: Operator | B17: =ROUNDUP(OPEX!B18/3,0) -> 2 | C17: person | D17: 75000 | E17: =D17*B17 -> 150000
A18: Driver | B18: =ROUNDUP(OPEX!B19/3,0)*2 -> 134 | C18: person | D18: 65000 | E18: =D18*B18 -> 8710000
A19: Total: | E19: =SUM(E18) -> 8710000
A22: Feedstock Preparation
A25: Variable Operating Cost
A26: Input | B26: Value Required | C26: Units | D26: Researched Values | H26: Scaled Cost
D27: Cost | E27: Units | F27: Year | G27: Source | H27: PPI 2024 | I27: Total Cost (per year)
A28: Power - Sand Removal | B28: =OPEX!B124*2 -> 404729.37 | C28: kWh/yr | D28: 0.178 | E28: kWh | F28: 2024 | H28: =CAPEX!N$3/389.544 -> 1.0332235 | I28: =B28*D28*H28 -> 74435.306
A29: Power - Water Pump | B29: =OPEX!B125*2 -> 419.21667 | C29: kWh/yr | D29: 0.178 | E29: kWh | F29: 2024 | H29: =CAPEX!N$3/389.544 -> 1.0332235 | I29: =B29*D29*H29 -> 77.099721
A30: Power - Manure Pump | B30: =OPEX!B126*2 -> 213.85147 | C30: kWh/yr | D30: 0.178 | E30: kWh | F30: 2024 | H30: =CAPEX!N$3/389.544 -> 1.0332235 | I30: =B30*D30*H30 -> 39.330232
A31: Power - Food Waste Pump | B31: =OPEX!B127*2 -> 152.30973 | C31: kWh/yr | D31: 0.178 | E31: kWh | F31: 2024 | H31: =CAPEX!N$3/389.544 -> 1.0332235 | I31: =B31*D31*H31 -> 28.011857
A32: Power - Manure Grinder | B32: =OPEX!B128*2 -> 23862.4 | C32: kWh/yr | D32: 0.178 | E32: kWh | F32: 2024 | H32: =CAPEX!N$3/389.544 -> 1.0332235 | I32: =B32*D32*H32 -> 4388.6241
A33: Power - Food Waste Grinder | B33: =OPEX!B129*2 -> 11931.2 | C33: kWh/yr | D33: 0.178 | E33: kWh | F33: 2024 | H33: =CAPEX!N$3/389.544 -> 1.0332235 | I33: =B33*D33*H33 -> 2194.312
A34: Total: | I34: =SUM(I28:I33) -> 81162.684
A38: Anaerobic Digestion
M39: NaOH Market Value Analysis
M40: kg NaOH | N40: USD
A41: Variable Operating Cost | M41: 1 | N41: 55
A42: Input | B42: Value Required | C42: Units | D42: Researched Values | H42: Scaled Cost | M42: 25 | N42: =380/25 -> 15.2
D43: Cost | E43: Units | F43: Year | G43: Source | H43: PPI 2024 | I43: Total Cost (per year) | M43: 40 | N43: 12
A44: Heat | B44: =(OPEX!B159+OPEX!B180)*2 -> 8720.8333 | C44: kWh/yr | D44: 0.178 | E44: kWh | F44: 2024 | H44: =CAPEX!N$3/389.544 -> 1.0332235 | I44: =H44*D44*B44 -> 1603.8814
A45: Power - Mixing | B45: =(OPEX!B160+OPEX!B181)*2 -> 7554423.4 | C45: kWh/yr | D45: 0.178 | E45: kWh | F45: 2024 | H45: =CAPEX!N$3/389.544 -> 1.0332235 | I45: =H45*D45*B45 -> 1389362.5
A46: NaOH Addition | B46: =BM_Flow!C97*Inputs!F13*2*Inputs!D170/1000*Inputs!F3 -> 2400000 | C46: kg/yr | D46: 2.48 | E46: kg (2 ton) | F46: 2024 | H46: 1 | I46: =H46*D46*B46 -> 5952000
A47: Power - Digester Pump | B47: =(OPEX!B161+OPEX!B182)*2 -> 35041.05 | C47: kg/yr | D47: 0.178 | E47: kWh | F47: 2024 | H47: =CAPEX!N$3/389.544 -> 1.0332235 | I47: =H47*D47*B47 -> 6444.5317
A48: Total: | I48: =SUM(I44:I47) -> 7349410.9
A50: Fixed Operational Cost: Labor
A51: Position | B51: Number Required | C51: Units | D51: 2024 Salary | E51: Total Cost (per year)
A52: PhD | B52: =ROUNDUP(OPEX!B166/3,0) -> 1 | C52: person | D52: 150000 | E52: =D52*B52 -> 150000
A53: MS / PE | B53: =ROUNDUP(OPEX!B167/3,0) -> 1 | C53: person | D53: 100000 | E53: =D53*B53 -> 100000
A54: BS | B54: =ROUNDUP(OPEX!B168/3,0) -> 2 | C54: person | D54: 85000 | E54: =D54*B54 -> 170000
...

Sheet BM_DCFROR
B2: Economic Inputs
B4: Capital and Operational Costs
B5: Operational cost | D5: =BM_OPEX!I119 -> 35207308
B6: Equipment and facilities capital cost | D6: =BM_CAPEX!O71 -> 1.6484269e+08
B7: Land capital cost | D7: =D6*0.15 -> 24726404
B8: Working capital | D8: =D6*0.05 -> 8242134.6
B10: Loan
B11: Equity | D11: 0.4
B12: Loan interest | D12: 0.08
B13: Loan term | D13: 10
B14: Annual loan payment | D14: =-PMT(D12,D13,D6*(1-D11)) -> 14739853
B16: Depreciation
B17: MACRS | C17: Years | D17: 7
B19: Construction Period
B20: Construciton period (years) | D20: 3
C21: % yr -2 | D21: 0.1
C22: % yr -1 | D22: 0.5
C23: % yr 0 | D23: 0.4
B25: Productivity
B26: Start up time | C26: Years | D26: 0.5
B27: Start up production | C27: % of full production | D27: 0.5
B31: Biomethane | C31: m3/yr | D31: =BM_Flow!E28*(BM_Flow!C43/100)*Inputs!F3*2 -> 9560947.5
B32: Fertilizer (?) | C32: kg/yr
B33: Waste Collection | C33: kg/yr | D33: =A_DCFROR!D33*2 -> 4.4828554e+08
B35: Internal Rate of Return and Tax Rate
B36: Internal rate of return | D36: 0.1
B37: Tax rate | D37: 0.35
B39: Results
B43: MSP BioMethane | C43: per m3 | D43: 4.8525 | H43: =D43/9.5 -> 0.51078947 | I43: $/kWh
B45: Waste Collection | C45: per kg | D45: 0.03
B47: Net Present Value | D47: =D86-SUM(E87:G87) -> -7025610.5
B49: Cash flow analysis
B51: Year | E51: -2 | F51: -1 | G51: 0 | H51: 1 | I51: 2 | J51: 3 | K51: 4 | L51: 5 | M51: 6 | N51: 7 | O51: 8 | P51: 9 | Q51: 10 | R51: 11 | S51: 12 | T51: 13 | U51: 14 | V51: 15 | W51: 16 | X51: 17 | Y51: 18 | Z51: 19 | AA51: 20 | AB51: 21 | AC51: 22 | AD51: 23 | AE51: 24 | AF51: 25 | AG51: 26 | AH51: 27 | AI51: 28 | AJ51: 29 | AK51: 30
B52: Equipment and facilities capital | E52: =($D$6*D21*$D$11) -> 6593707.7 | F52: =($D$6*D22*$D$11) -> 32968539 | G52: =$D$6*D23*$D$11 -> 26374831
B53: Land capital | E53: =D7 -> 24726404
B54: Working capital | G54: =D8 -> 8242134.6
